<?xml version="1.0"?>

<robot xmlns:xacro="http://www.ros.org/wiki/xacro" name="hospital_bot">

     
     <xacro:arg name="is_sim" default="true"/>
 
     <xacro:include filename="$(find hospital_bot_description)/urdf/hospital_bot_gazebo.xacro"/>

     <xacro:include filename="$(find hospital_bot_description)/urdf/hospital_bot_ros2_control.xacro"/>

     <link name="base_footprint"/>

     <link name="base_link">
          <inertial>
               <origin xyz="0 0 0.04" rpy="0.0 0.25 0.3"/>
               <mass value="8.2573504e-01"/>
               <inertia ixx="2.2124416e-02" ixy="-1.2294101e-04" ixz="3.4938785e-04"
                         iyy="2.1193702e-02" iyz="-5.0120904e-05"
                         izz="2.0064271e-02"/>
          </inertial>
          <visual>
               <origin rpy="0 0 0" xyz="0 0 0"/>
               <geometry>
                    <mesh filename="package://hospital_bot_description/meshes/base_link.STL"/>
               </geometry>
          </visual>
          <collision>
               <origin rpy="0 0 0" xyz="0 0 0"/>
               <geometry>
                    <mesh filename="package://hospital_bot_description/meshes/base_link.STL"/>
               </geometry>
          </collision>
     </link>

     <joint name="base_joint" type="fixed">
          <parent link="base_footprint"/>
          <child link="base_link"/>
          <origin rpy="0 0 0" xyz="0 0 0.033"/>
     </joint>

     <link name="wheel_right_link">
          <inertial>
               <origin xyz="0 -0.014 0" rpy="0 0 0"/>
               <mass value="0.0530086090966721"/>
               <inertia ixx="1.8817629833666E-05" ixy="-4.8444E-10" ixz="1.88163E-08"
                         iyy="3.1151E-05" iyz="-6.9356E-11"
                         izz="1.8801E-05"/>
          </inertial>
          <visual>
               <origin rpy="1.57 0 0" xyz="0 0 0"/>
               <geometry>
                    <mesh filename="package://hospital_bot_description/meshes/wheel_right_link.STL"/>
               </geometry>
          </visual>
          <collision>
               <origin xyz="0 -0.015 0" rpy="1.57 0 0"/>
               <geometry>
                    <sphere radius="0.033"/>
               </geometry>
          </collision>
     </link>

     <joint name="wheel_right_joint" type="continuous">
          <parent link="base_link"/>
          <child link="wheel_right_link"/>
          <axis xyz="0 1 0"/>
          <origin rpy="0 0 0" xyz="0 -0.07 0"/>
     </joint>

     <link name="wheel_left_link">
          <inertial>
               <origin xyz="0 0.014 0" rpy="0 0 0"/>
               <mass value="0.0530086090966721"/>
               <inertia ixx="1.8817629833666E-05" ixy="-4.8444E-10" ixz="1.88163E-08"
                         iyy="3.1151E-05" iyz="-6.9356E-11"
                         izz="1.8801E-05"/>
          </inertial>
          <visual>
               <origin rpy="-1.57 0 0" xyz="0 0 0"/>
               <geometry>
                    <mesh filename="package://hospital_bot_description/meshes/wheel_left_link.STL"/>
               </geometry>
          </visual>
          <collision>
               <origin xyz="0 0.015 0" rpy="1.57 0 0"/>
               <geometry>
                    <sphere radius="0.033"/>
               </geometry>
          </collision>
     </link>

     <joint name="wheel_left_joint" type="continuous">
          <parent link="base_link"/>
          <child link="wheel_left_link"/>
          <axis xyz="0 1 0"/>
          <origin rpy="0 0 0" xyz="0 0.07 0"/>
     </joint>

     <link name="caster_front_link">
          <inertial>
               <origin xyz="3.899E-07 2.4007E-07 0.002191" rpy="0 0 0"/>
               <mass value="1.4437E-06"/>
               <inertia ixx="7.2307E-11" ixy="-6.1095E-16" ixz="2.2284E-15"
                         iyy="3.871E-11" iyz="2.939E-15"
                         izz="1.009E-10"/>
          </inertial>
          <visual>
               <origin rpy="0 0 0" xyz="0 0 0"/>
               <geometry>
                    <mesh filename="package://hospital_bot_description/meshes/caster_front_link.STL"/>
               </geometry>
          </visual>
          <collision>
               <origin xyz="0 0 0" rpy="0 0 0"/>
               <geometry>
                    <sphere radius="0.005"/>
               </geometry>
          </collision>
     </link>

     <joint name="caster_front_joint" type="fixed">
          <parent link="base_link"/>
          <child link="caster_front_link"/>
          <origin rpy="0 0 0" xyz="0.04755 0 -0.0275"/>
     </joint>

     <link name="caster_rear_link">
          <inertial>
               <origin xyz="3.899E-07 2.4007E-07 0.002191" rpy="0 0 0"/>
               <mass value="1.4437E-06"/>
               <inertia ixx="7.2307E-11" ixy="-6.1095E-16" ixz="2.2284E-15"
                         iyy="3.871E-11" iyz="2.939E-15"
                         izz="1.009E-10"/>
          </inertial>
          <visual>
               <origin rpy="0 0 0" xyz="0 0 0"/>
               <geometry>
                    <mesh filename="package://hospital_bot_description/meshes/caster_rear_link.STL"/>
               </geometry>
          </visual>
          <collision>
               <origin xyz="0 0 0" rpy="0 0 0"/>
               <geometry>
                    <sphere radius="0.005"/>
               </geometry>
          </collision>
     </link>

     <joint name="caster_rear_joint" type="fixed">
          <parent link="base_link"/>
          <child link="caster_rear_link"/>
          <origin rpy="0 0 0" xyz="-0.04755 0 -0.0275"/>
     </joint>

     <link name="imu_link">
          <inertial>
               <origin xyz="-0.005524 0.000168 0.000514" rpy="0 0 0"/>
               <mass value="0.0005284"/>
               <inertia ixx="1.4617E-08" ixy="1.40015E-10" ixz="-1.99633E-12"
                         iyy="8.59662E-09" iyz="7.5237E-12"
                         izz="2.30279E-08"/>
          </inertial>
          <visual>
               <origin xyz="0 0 0" rpy="0 0 0"/>
               <geometry>
                    <mesh filename="package://hospital_bot_description/meshes/imu_link.STL"/>
               </geometry>
          </visual>
          <collision>
               <origin xyz="0 0 0" rpy="0 0 0"/>
               <geometry>
                    <mesh filename="package://hospital_bot_description/meshes/imu_link.STL"/>
               </geometry>
          </collision>
     </link>

     <joint name="imu_joint" type="fixed">
          <origin xyz="0 0 0.07" rpy="3.14 0 0"/>  <!-- Fixed typo here -->
          <parent link="base_link"/>
          <child link="imu_link"/>
          <axis xyz="0 0 0"/>
     </joint>
     

     <link name="laser_link">
          <inertial>
               <origin xyz="-0.0119 -0.00038 -0.01706" rpy="0 0 0"/>
               <mass value="0.07308"/>
               <inertia ixx="1.9607E-05" ixy="-3.6209E-07" ixz="4.2823E-07"
                         iyy="2.4098E-05" iyz="1.501809E-08"
                         izz="4.1418E-05"/>
          </inertial>
          <visual>
               <origin xyz="0 0 0" rpy="0 0 0"/>
               <geometry>
                    <mesh filename="package://hospital_bot_description/meshes/laser_link.STL"/>
               </geometry>
          </visual>
          <collision>
               <origin xyz="0 0 0" rpy="0 0 0"/>
               <geometry>
                    <mesh filename="package://hospital_bot_description/meshes/laser_link.STL"/>
               </geometry>
          </collision>
     </link>

     <joint name="laser_joint" type="fixed">
          <parent link="base_link"/>
          <child link="laser_link"/>
          <origin xyz="0.0 0.0 0.1208" rpy="0 0 3.14"/>
     </joint>

</robot>
